---
layout:     post                   
title:      Java05异常处理
subtitle:   Java异常处理涉及到五个关键字，分别是：try、catch、finally、throw、throws
date:       2019-09-22        
author:     HY                 
header-img: img/post-bg-2015.jpg
catalog: true                  
tags:                   
    - Java
    - 异常
---

# Java05：异常处理

## 1 Java的异常

### 1.1 异常概念

- 异常指的是程序在执行过程中，出现的非正常的情况，最终会导致JVM的非正常停止。

- 异常是一个类，产生异常就是创建异常对象并抛出了一个异常对象。
- 异常可以在任何地方抛出，但只需要在上层捕获，这样就和方法调用分离了。
- Java处理异常的方式是中断处理。

### 1.2 异常体系

Java的异常是`class`，它的继承关系如下：

![](https://raw.githubusercontent.com/hihanying/FigureBed/master/img/1569146870(1).png)



从继承关系可知：`Throwable`是异常体系的根，它继承自`Object`。`Throwable`有两个体系：`Error`和`Exception`。

1. `Error`表示严重的错误，程序对此一般无能为力，当出现这些异常时，Java虚拟机（JVM）一般会选择终止线程。例如：
    - `OutOfMemoryError`：内存耗尽
    - `NoClassDefFoundError`：无法加载某个Class
    - `StackOverflowError`：栈溢出

2. `Exception`则是运行时的错误，它可以被捕获并处理，并且在程序中应该尽可能的去处理这些异常。
   - 某些异常是应用程序逻辑处理的一部分，应该捕获并处理。例如：
      - `NumberFormatException`：数值类型的格式错误
      - `FileNotFoundException`：未找到文件
      - `SocketException`：读取网络失败
   - 一些异常是程序逻辑编写不对造成的，应该修复程序本身。例如：
      - `NullPointerException`：对某个`null`的对象调用方法或字段
      - `IndexOutOfBoundsException`：数组索引越界

`Exception`又分为两大类：

1. 运行时异常：`RuntimeException`及其子类。这些异常是不检查异常，程序中可以选择捕获处理，也可以不处理。这些异常一般是由程序逻辑错误引起的，程序应该从逻辑角度尽可能避免这类异常的发生；
2. 编译时异常：`RuntimeException`之外的异常我们统称为非运行时异常，类型上属于`Exception`类及其子类，从程序语法角度讲是必须进行处理的异常，如果不处理，程序就不能编译通过。

> Java规定：
>
> - 必须捕获的异常（检查异常），包括`Exception`及其子类，但不包括`RuntimeException`及其子类，这种类型的异常称为Checked Exception。
> - 不需要捕获的异常（不受检查异常），包括`Error`及其子类，`RuntimeException`及其子类。



## 2 异常的处理

Java的异常处理本质上是**抛出异常**和**捕获异常**。

Java异常处理涉及到五个关键字，分别是：`try`、`catch`、`finally`、`throw`、`throws`。

　　• **try**        -- 用于监听异常。将可能抛出异常的代码放在try语句块之内，当其发生异常时，异常就被抛出。
　　• **catch**   -- 用于捕获异常。catch用来捕获try语句块中发生的异常。
　　• **finally**  -- finally语句块总是会被执行。主要用于回收在try块里打开的资源（释放资源）。
　　• **throw**   -- 用于抛出异常。
　　• **throws** -- 用在方法签名中，用于声明该方法可能抛出的异常。

### 2.1 捕获异常`try,catch,finally`

`try`关键字用来包围可能会出现异常的逻辑代码，它单独无法使用，必须配合`catch`或者`finally`使用。

语法如下：

```java
try{
   // 可能产生异常的程序代码
}catch(ExceptionName e1){
    e1.printStackTrace();   // 处理异常e1的代码
}catch(ExceptionName e2){
    e2.printStackTrace();   // 处理异常e2的代码
}finally{
    //
}
```

其中，`catch`块可以有多个，注意`try`块只能有一个，`finally`块是可选的（但是最多只能有一个finally块）。

> 注意：
>
> - 三个块执行的顺序为try—>catch—>finally。
> - 如果没有发生异常，就正常执行`try { ... }`语句块，然后执行`finally`。如果发生了异常，就中断执行`try { ... }`语句块，然后跳转执行匹配的`catch`语句块，最后执行`finally`。
> - 在有多个catch块的时候，是按照catch块的先后顺序进行匹配的，一旦异常类型被一个catch块匹配，则不会与后面的catch块进行匹配。因此，多个`catch`语句的匹配顺序非常重要，子类必须放在前面，否则子类可能会被父类屏蔽。
> - 在使用try..catch..finally块的时候，注意千万不要在finally块中使用return，因为finally中的return会覆盖已有的返回值。



**获取异常信息：**

Throwable类中定义了一些查看方法:

- `public String getMessage()`:获取异常的描述信息,原因(提示给用户的时候,就提示错误原因。

- `public String toString()`:获取异常的类型和异常描述信息(不用)。
- `public void printStackTrace()`:打印异常的跟踪栈信息并输出到控制台。



### 2.2 抛出异常`throw,throws`

当发生错误时，例如，用户输入了非法的字符，我们就可以抛出异常。

**抛出异常分两步：**

1. 创建某个`Exception`的实例；
2. 用`throw`语句抛出。

throw用在方法内，用来抛出一个异常对象，将这个异常对象传递到调用者处，并结束当前方法的执行。

```java
public class ThrowDemo {
    public static void main(String[] args) {
        int[] arr = {2,4,52,2};//创建一个数组 
        int element = getElement(arr, 4);//根据索引找对应的元素 
        System.out.println(element);
	}
    public static int getElement(int[] arr,int index){ 
        if(index<0 || index>arr.length-1){//判断索引是否越界
             throw new ArrayIndexOutOfBoundsException("索引越界异常");//中止，向调用者抛出异常
        }
        int element = arr[index];
        return element;
    }
}
```
> **`Objects.requireNonNull(obj)`非空判断：**
>
> `public static <T> T requireNonNull(T obj)`:查看指定引用对象不是null。
>
> 其源码：
>
> ```java
> public static <T> T requireNonNull(T obj) {
>  if (obj == null)
>    	throw new NullPointerException();
>  return obj;
> }
> ```



**异常类型“转换”：**

如果一个方法捕获了某个异常后，又在`catch`子句中抛出新的异常，就相当于把抛出的异常类型“转换”了：

```java
void process1(String s) {
    try {
        process2();
    } catch (NullPointerException e) {
        throw new IllegalArgumentException();
    }
}
void process2(String s) {
    if (s==null) {
        throw new NullPointerException();
    }
}
```

**获取原始异常**

如果在`main()`中捕获`IllegalArgumentException`，新的异常会丢失原始异常信息，看不到原始异常`NullPointerException`的信息。为了能追踪到完整的异常栈，在构造异常的时候，把原始的`Exception`实例传进去，新的`Exception`就可以持有原始`Exception`信息。

```java
public class Main {
    public static void main(String[] args) {
        try {
            process1();
        } catch (Exception e) {
            e.printStackTrace();
        }
    }
    static void process1() {
        try {
            process2();
        } catch (NullPointerException e) {
            throw new IllegalArgumentException(e);//传递原始的异常NullPointerException
        }
    }
    static void process2() {
        throw new NullPointerException();
    }
}
```



**异常屏蔽**

在`try`或者`catch`语句块中抛出异常，不会影响`finally`的执行。JVM会先执行`finally`，然后抛出异常。

```java
public class Main {
    public static void main(String[] args) {
        try {
            Integer.parseInt("abc");
        } catch (Exception e) {
            System.out.println("catched");
            throw new RuntimeException(e);
        } finally {
            System.out.println("finally");
        }
    }
}
```

如果在执行`finally`语句时抛出异常，原来在`catch`中准备抛出的异常就“消失”了，因为只能抛出一个异常。没有被抛出的异常称为**被屏蔽**的异常（Suppressed Exception）。

在极少数的情况下，我们需要获知所有的异常。方法是先用`origin`变量保存原始异常，然后调用`Throwable.addSuppressed()`，把原始异常添加进来，最后在`finally`抛出：

```java
public class Main {
    public static void main(String[] args) throws Exception {
        Exception origin = null;
        try {
            System.out.println(Integer.parseInt("abc"));
        } catch (Exception e) {
            origin = e;
            throw e;
        } finally {
            Exception e = new IllegalArgumentException();
            if (origin != null) {
                e.addSuppressed(origin);
            }
            throw e;
        }
    }
}
```

绝大多数情况下，在`finally`中不要抛出异常。




**声明异常**

除了手动显式的使用`throw`抛出异常之外，还可以在可能出现异常的方法声明时使用`throws`抛出交给调用者去执行。`throws` 关键字放在方法签名的尾部，若该方法可能有多种异常情况产生，那么在`throws`后面可以写多个异常类，用逗号隔开。

```java
class TestThrows{
    static void throw1() throws IllegalAccessException {
        System.out.println("Inside throw1 . ");
        throw new IllegalAccessException("demo");
    }
    public static void main(String[] args){
        try {
            throw1();
        }catch(IllegalAccessException e ){
            System.out.println("Caught " + e);
        }
    }
}
```
`Throws`抛出异常的规则：

- 如果是不受检查异常（`unchecked exception`），即`Error`、`RuntimeException`或它们的子类，那么可以不使用`throws`关键字来声明要抛出的异常，编译仍能顺利通过，但在运行时会被系统抛出。
- 任何检查异常（`checked exception`）必须使用 `throws` 关键字来声明。即如果一个方法可能出现受可查异常，要么用`try-catch`语句捕获，要么用`throws`子句声明将它抛出，否则会导致编译错误。
- 仅当抛出了异常，该方法的调用者才必须处理或者重新抛出该异常。当方法的调用者无力处理该异常的时候，应该继续向上抛出。
- 调用方法必须遵循任何可查异常的处理和声明规则。若覆盖一个方法，则不能声明与覆盖方法不同的异常。声明的任何异常必须是被覆盖方法所声明异常的同类或子类。



## 3 自定义异常



当我们在代码中需要抛出异常时，尽量使用JDK已定义的异常类型。

在一个大型项目中，可以自定义新的异常类型

一个常见的做法是自定义一个`BaseException`作为“根异常”，然后，派生出各种业务类型的异常。

`BaseException`需要从一个适合的`Exception`派生，通常建议从`RuntimeException`派生：

```java
public class BaseException extends RuntimeException {}
```

其他业务类型的异常就可以从`BaseException`派生：

```java
public class UserNotFoundException extends BaseException {}
public class LoginFailedException extends BaseException {}
...
```























